Being very new to Phyton, I’m trying to use tktable for Python and can’t get it run on my PC. After searching a lot in the net, 
without finding any solution, I hope you find the time to help me a bit. I’m sure this is peanuts for you.

I’m running Python 3.7 on a Windows 8.1. PC.

I’m getting this error:


_tkinter.TclError: invalid command name "table"

What I did so far:
1.Downloaded tktable and run the setup.py.
2.Copied the tktable.py to the Python site-packages folder.
3.Installed ActiveTcl.
4.Copied the three files tktable.tcl, Tktable.dll and pkgIndex.tcl from ActiveTcl (C:\ActiveTcl\lib\Tktable2.11) to 
  C:........\Python\Python37-32\tcll\Tktable2.11.
5.According what I have found in the net, this should do it…

But, as I wrote, I keep getting the error I mentioned.

Michael

The content is:
C:\Users\mschuppisser.EAD\AppData\Local\Programs\Python\Python37-32\Lib\;
C:\Users\mschuppisser.EAD\AppData\Local\Programs\Python\Python37-32\DLLs\


Traceback: 
Exception in Tkinter callback
Traceback (most recent call last):
  File "C:\Users\mschuppisser.EAD\AppData\Local\Programs\Python\Python37-32\lib\tkinter\__init__.py", line 1705, in __call__
    return self.func(*args)
  File "C:/Users/mschuppisser.EAD/Data/My Data/Python/Test Applikation/Test Applikation.py", line 267, in Jump_to_UebersichtsFenster3
    application = clsUebersichtsFenster3(UebersichtsFenster3)
  File "C:/Users/mschuppisser.EAD/Data/My Data/Python/Test Applikation/Test Applikation.py", line 447, in __init__
    self.table_grid = tktable.Table(UebersichtsFenster3) # , state='disabled', width=50, titlerows=1, rows=5, cols=4, colwidth=20)
  File "C:\Users\mschuppisser.EAD\AppData\Local\Programs\Python\Python37-32\lib\site-packages\tktable.py", line 135, in __init__
    tkinter.Widget.__init__(self, master, 'table', kw)
  File "C:\Users\mschuppisser.EAD\AppData\Local\Programs\Python\Python37-32\lib\tkinter\__init__.py", line 2299, in __init__
    (widgetName, self._w) + extra + self._options(cnf))
_tkinter.TclError: invalid command name "table"

=================================================================

In the meanwhile I had a look at the tktable.py script itself. The command that is causing the error is 
os.environ.get("TKTABLE_LIBRARY") returning a None value. 
This means that the environment variable TKTABLE_LIBRARY is not there. 
I checked this and created it myself. Now I’m getting a new error:

Exception in Tkinter callback 
Traceback (most recent call last): 
File "C:\Users\mschuppisser.EAD\AppData\Local\Programs\Python\Python37-32\lib\tkinter__init__.py", line 1705, 
in call return self.func(*args) File "C:/Users/mschuppisser.EAD/Data/My Data/Python/Test Applikation/Test Applikation.py", line 271, 
in Jump_to_UebersichtsFenster3 application = clsUebersichtsFenster3(UebersichtsFenster3) File "C:/Users/mschuppisser.EAD/Data/My Data/Python/Test Applikation/Test Applikation.py", line 472, 
in init self.tktable = tktable.Table(UebersichtsFenster3) # , state='disabled', width=50, titlerows=1, rows=5, cols=4, colwidth=20) File "C:\Users\mschuppisser.EAD\AppData\Local\Programs\Python\Python37-32\Lib\lib-tk\tktable.py", line 126, 
in init 'global auto_path; lappend auto_path {%s}' % tktable_lib) 
_tkinter.TclError: missing close-brace

Process finished with exit code 0

Here the command that is causing it in script tkTable.py:
            master.tk.eval(
                'global auto_path; lappend auto_path {%s}' % tktable_lib)

Braces are there…. Any ideas?

